{
 "cells": [
  {
   "cell_type": "markdown",
   "metadata": {},
   "source": [
    "## LLM Emotional Response For Paintings"
   ]
  },
  {
   "cell_type": "markdown",
   "metadata": {},
   "source": [
    "### Model information: Gemini 2.5 flash\n",
    "### output \"free_emo_model.csv\" "
   ]
  },
  {
   "cell_type": "code",
   "execution_count": 15,
   "metadata": {},
   "outputs": [],
   "source": [
    "#import libraries\n",
    "\n",
    "from google import genai\n",
    "from google.genai import types\n",
    "from google.api_core import exceptions as google_exceptions\n",
    "from concurrent.futures import ThreadPoolExecutor, as_completed\n",
    "from pathlib import Path\n",
    "\n",
    "import os\n",
    "import re\n",
    "import time\n",
    "import random\n",
    "import logging, sys\n",
    "from pathlib import Path\n",
    "import mimetypes\n",
    "\n",
    "import pandas as pd\n",
    "from tqdm import tqdm\n",
    "from PIL import Image\n",
    "from functools import reduce\n",
    "\n",
    "logging.basicConfig(\n",
    "    stream=sys.stdout,             \n",
    "    format=\"%(asctime)s [%(levelname)s] %(message)s\",\n",
    "    datefmt=\"%H:%M:%S\")"
   ]
  },
  {
   "cell_type": "markdown",
   "metadata": {},
   "source": [
    "#### For each emotion, write one model to produce output. Plus one aesthetic rating model."
   ]
  },
  {
   "cell_type": "code",
   "execution_count": 63,
   "metadata": {},
   "outputs": [],
   "source": [
    "# ——— CONFIGURATION ———————————————————————————————————————————————————————————————————\n",
    "IMAGE_FOLDER      = Path(\"/Users/Stella/Desktop/EmotionArt/emotion-art/data/exp_images/abstract\")\n",
    "OUTPUT_CSV        = Path(\"free_emo_model.csv\")\n",
    "MODEL_NAME        = \"gemini-2.5-flash\"\n",
    "MAX_RETRIES       = 6\n",
    "BACKOFF_BASE      = 3.0\n",
    "BATCH_SIZE        = 10\n",
    "MAX_OUTPUT_TOKENS = 2049\n",
    "IMAGE_EXTS        = {\".jpg\", \".jpeg\", \".png\", \".bmp\", \".gif\", \".tiff\"}"
   ]
  },
  {
   "cell_type": "code",
   "execution_count": 64,
   "metadata": {},
   "outputs": [],
   "source": [
    "# ——— LOGGING ———————————————————————————————————————————————————————————————————————\n",
    "logging.basicConfig(\n",
    "    stream=sys.stdout,             \n",
    "    format=\"%(asctime)s [%(levelname)s] %(message)s\",\n",
    "    datefmt=\"%H:%M:%S\"\n",
    ")"
   ]
  },
  {
   "cell_type": "code",
   "execution_count": 65,
   "metadata": {},
   "outputs": [],
   "source": [
    "# ——— HELPER FUNCTIONS —————————————————————————————————————————————————————————————————\n",
    "def get_mime_type(path: str) -> str:\n",
    "    mime, _ = mimetypes.guess_type(path)\n",
    "    return mime or \"application/octet-stream\"\n",
    "\n",
    "def is_image_file(path: Path) -> bool:\n",
    "    return path.is_file() and path.suffix.lower() in IMAGE_EXTS and not path.name.startswith(\".\")\n",
    "\n",
    "_SCORE_RE = re.compile(r\"^[A-Za-z]+:\\s*([\\d.]+)\", re.MULTILINE)\n",
    "_EXPL_RE  = re.compile(r\"Explanation:\\s*(.*)\", re.DOTALL)\n",
    "\n",
    "def parse_response(raw: str) -> tuple[float|None, str]:\n",
    "    text = raw.decode(\"utf-8\", errors=\"ignore\") if isinstance(raw, (bytes, bytearray)) else str(raw or \"\")\n",
    "    m_score = _SCORE_RE.search(text)\n",
    "    m_expl  = _EXPL_RE.search(text)\n",
    "    if not (m_score and m_expl):\n",
    "        return None, text.strip()\n",
    "    return float(m_score.group(1)), m_expl.group(1).strip()\n",
    "\n",
    "#for batch processing\n",
    "def chunker(seq, size):\n",
    "    for i in range(0, len(seq), size):\n",
    "        yield seq[i : i + size]\n"
   ]
  },
  {
   "cell_type": "code",
   "execution_count": 66,
   "metadata": {},
   "outputs": [],
   "source": [
    "def free_emotion_prompt() -> str:\n",
    "    return (\n",
    "        \"You are an average American citizen evaluating your emotional response to a painting.\\n\"\n",
    "        \"Provide a single free-form paragraph describing how viewing this painting makes you feel emotionally. \"\n",
    "        \"Feel free to mention anything that helps convey your emotional reaction.\"\n",
    "    )"
   ]
  },
  {
   "cell_type": "code",
   "execution_count": 67,
   "metadata": {},
   "outputs": [],
   "source": [
    "def free_emotion_prompt2() -> str:\n",
    "    return (\n",
    "        \"You are an average American citizen evaluating your emotional response to a painting.\\n\"\n",
    "        \"Provide a single free-form paragraph describing how viewing this painting makes you feel emotionally. \"\n",
    "        \"Focus on all the emotional responses that come to mind, \"\n",
    "        \"including any specific words or phrases that capture your emotional reaction.\\n\"\n",
    "        \"Only include what you feel, not what you do not feel or what it is not.\"\n",
    "    )"
   ]
  },
  {
   "cell_type": "code",
   "execution_count": 68,
   "metadata": {},
   "outputs": [],
   "source": [
    "# ——— PRELOAD IMAGES AND PROMPTS ——————————————————————————————————————————————————————————\n",
    "all_images  = sorted(p for p in IMAGE_FOLDER.iterdir() if is_image_file(p))\n",
    "\n",
    "# ——— VERTEX AI CLIENT FACTORY —————————————————————————————————————————————————————————\n",
    "def make_vertex_client():\n",
    "    return genai.Client(\n",
    "        vertexai=True,\n",
    "        project=\"emotion-art-analysis\",\n",
    "        location=\"global\",\n",
    "    )\n"
   ]
  },
  {
   "cell_type": "code",
   "execution_count": 69,
   "metadata": {},
   "outputs": [],
   "source": [
    "# instead of .iterdir(), use .rglob() to find images in any subdirectory\n",
    "all_images = sorted(\n",
    "    p for p in IMAGE_FOLDER.rglob(\"*\")\n",
    "    if is_image_file(p)\n",
    ")\n"
   ]
  },
  {
   "cell_type": "code",
   "execution_count": 70,
   "metadata": {},
   "outputs": [],
   "source": [
    "# ——— CORE EMOTION CALL —————————————————————————————————————————————————————————————————\n",
    "def emotion_model_vertex(image_path: str, client) -> dict:\n",
    "    \n",
    "    image_path = Path(image_path)\n",
    "    image_name = image_path.name\n",
    "    image_category = image_path.parent.name\n",
    "    with open(image_path,\"rb\") as img_file:\n",
    "        image_bytes = img_file.read()\n",
    "        \n",
    "    mime_type = get_mime_type(image_path)\n",
    "\n",
    "    prompt_text = free_emotion_prompt2()\n",
    "\n",
    "    for attempt in range(1, MAX_RETRIES + 1):\n",
    "        try:\n",
    "            resp = client.models.generate_content(\n",
    "                model   = MODEL_NAME,\n",
    "                contents = [\n",
    "                    types.Part.from_bytes(data=image_bytes, mime_type=mime_type),\n",
    "                    types.Part.from_text(text=prompt_text),\n",
    "                ],\n",
    "                config = types.GenerateContentConfig(\n",
    "                    max_output_tokens=MAX_OUTPUT_TOKENS\n",
    "                )\n",
    "            )\n",
    "\n",
    "            raw = resp.candidates[0].content.parts[0].text if resp.candidates else \"\"\n",
    "            \n",
    "            return {\n",
    "                \"image\": image_name,\n",
    "                \"image_category\": image_category,\n",
    "                \"free_response\":      raw\n",
    "            }\n",
    "\n",
    "        except google_exceptions.ServiceUnavailable:\n",
    "            backoff = min(BACKOFF_BASE * 2 ** (attempt - 1), 30) + random.random()\n",
    "            logging.warning(f\"503 overload (try {attempt}), sleeping {backoff:.1f}s\")\n",
    "            time.sleep(backoff)\n",
    "\n",
    "        except Exception as e:\n",
    "            backoff = min(BACKOFF_BASE * 2 ** (attempt - 1), 30) + random.random()\n",
    "            logging.warning(f\"Error on try {attempt}: {e}\")\n",
    "            time.sleep(backoff)\n",
    "\n",
    "    return {\n",
    "        \"image\": image_name,\n",
    "        \"image_category\": image_category,\n",
    "        \"free_response\": raw\n",
    "    }\n"
   ]
  },
  {
   "cell_type": "code",
   "execution_count": 71,
   "metadata": {},
   "outputs": [],
   "source": [
    "def call_vertex_for_image(image_path: Path, client) -> dict:\n",
    "    image_name     = image_path.name\n",
    "    image_category = image_path.parent.name\n",
    "    prompt_text    = free_emotion_prompt2()\n",
    "\n",
    "    with open(image_path, \"rb\") as f:\n",
    "        image_bytes = f.read()\n",
    "    mime_type = get_mime_type(image_path)\n",
    "\n",
    "    raw = \"\"\n",
    "    for attempt in range(1, MAX_RETRIES + 1):\n",
    "        try:\n",
    "            resp = client.models.generate_content(\n",
    "                model=MODEL_NAME,\n",
    "                contents=[\n",
    "                    types.Part.from_bytes(data=image_bytes, mime_type=mime_type),\n",
    "                    types.Part.from_text(text=prompt_text),\n",
    "                ],\n",
    "                config=types.GenerateContentConfig(\n",
    "                    max_output_tokens=MAX_OUTPUT_TOKENS\n",
    "                )\n",
    "            )\n",
    "            raw = resp.candidates[0].content.parts[0].text if resp.candidates else \"\"\n",
    "            break\n",
    "\n",
    "        except google_exceptions.ServiceUnavailable:\n",
    "            backoff = min(BACKOFF_BASE * 2**(attempt - 1), 30) + random.random()\n",
    "            logging.warning(f\"503 (try {attempt}), sleeping {backoff:.1f}s\")\n",
    "            time.sleep(backoff)\n",
    "\n",
    "        except Exception as e:\n",
    "            backoff = min(BACKOFF_BASE * 2**(attempt - 1), 30) + random.random()\n",
    "            logging.warning(f\"Error on try {attempt}: {e}\", exc_info=True)\n",
    "            time.sleep(backoff)\n",
    "\n",
    "    return {\n",
    "        \"image\":          image_name,\n",
    "        \"image_category\": image_category,\n",
    "        \"free_response\":  raw\n",
    "    }"
   ]
  },
  {
   "cell_type": "code",
   "execution_count": 72,
   "metadata": {},
   "outputs": [],
   "source": [
    "def process_all_images_in_batches(\n",
    "    image_paths: list[Path],\n",
    "    batch_size: int = BATCH_SIZE,\n",
    "    max_workers: int = 8\n",
    ") -> pd.DataFrame:\n",
    "    client  = make_vertex_client()\n",
    "    records = []\n",
    "\n",
    "    # chunk through your images\n",
    "    for batch in chunker(image_paths, batch_size):\n",
    "        with ThreadPoolExecutor(max_workers=max_workers) as exe:\n",
    "            futures = {\n",
    "                exe.submit(call_vertex_for_image, img, client): img\n",
    "                for img in batch\n",
    "            }\n",
    "            for future in as_completed(futures):\n",
    "                img = futures[future]\n",
    "                try:\n",
    "                    rec = future.result()\n",
    "                except Exception as e:\n",
    "                    logging.error(f\"❌ Error on {img.name}: {e}\", exc_info=True)\n",
    "                    rec = {\n",
    "                        \"image\":          img.name,\n",
    "                        \"image_category\": img.parent.name,\n",
    "                        \"free_response\":  f\"ERROR: {e}\"\n",
    "                    }\n",
    "                records.append(rec)\n",
    "\n",
    "    df = pd.DataFrame(records)\n",
    "    return df"
   ]
  },
  {
   "cell_type": "code",
   "execution_count": 73,
   "metadata": {},
   "outputs": [
    {
     "name": "stdout",
     "output_type": "stream",
     "text": [
      "17:51:06 [WARNING] Error on try 1: 429 RESOURCE_EXHAUSTED. {'error': {'code': 429, 'message': 'Resource exhausted. Please try again later. Please refer to https://cloud.google.com/vertex-ai/generative-ai/docs/error-code-429 for more details.', 'status': 'RESOURCE_EXHAUSTED'}}\n",
      "Traceback (most recent call last):\n",
      "  File \"/var/folders/_k/84ry5gsj3bnd86w91nlcyck00000gr/T/ipykernel_88795/3697096895.py\", line 13, in call_vertex_for_image\n",
      "    resp = client.models.generate_content(\n",
      "           ^^^^^^^^^^^^^^^^^^^^^^^^^^^^^^^\n",
      "  File \"/opt/anaconda3/lib/python3.12/site-packages/google/genai/models.py\", line 5898, in generate_content\n",
      "    response = self._generate_content(\n",
      "               ^^^^^^^^^^^^^^^^^^^^^^^\n",
      "  File \"/opt/anaconda3/lib/python3.12/site-packages/google/genai/models.py\", line 4838, in _generate_content\n",
      "    response = self._api_client.request(\n",
      "               ^^^^^^^^^^^^^^^^^^^^^^^^^\n",
      "  File \"/opt/anaconda3/lib/python3.12/site-packages/google/genai/_api_client.py\", line 1067, in request\n",
      "    response = self._request(http_request, stream=False)\n",
      "               ^^^^^^^^^^^^^^^^^^^^^^^^^^^^^^^^^^^^^^^^^\n",
      "  File \"/opt/anaconda3/lib/python3.12/site-packages/google/genai/_api_client.py\", line 958, in _request\n",
      "    return self._retry(self._request_once, http_request, stream)  # type: ignore[no-any-return]\n",
      "           ^^^^^^^^^^^^^^^^^^^^^^^^^^^^^^^^^^^^^^^^^^^^^^^^^^^^^\n",
      "  File \"/opt/anaconda3/lib/python3.12/site-packages/tenacity/__init__.py\", line 475, in __call__\n",
      "    do = self.iter(retry_state=retry_state)\n",
      "         ^^^^^^^^^^^^^^^^^^^^^^^^^^^^^^^^^^\n",
      "  File \"/opt/anaconda3/lib/python3.12/site-packages/tenacity/__init__.py\", line 376, in iter\n",
      "    result = action(retry_state)\n",
      "             ^^^^^^^^^^^^^^^^^^^\n",
      "  File \"/opt/anaconda3/lib/python3.12/site-packages/tenacity/__init__.py\", line 418, in exc_check\n",
      "    raise retry_exc.reraise()\n",
      "          ^^^^^^^^^^^^^^^^^^^\n",
      "  File \"/opt/anaconda3/lib/python3.12/site-packages/tenacity/__init__.py\", line 185, in reraise\n",
      "    raise self.last_attempt.result()\n",
      "          ^^^^^^^^^^^^^^^^^^^^^^^^^^\n",
      "  File \"/opt/anaconda3/lib/python3.12/concurrent/futures/_base.py\", line 449, in result\n",
      "    return self.__get_result()\n",
      "           ^^^^^^^^^^^^^^^^^^^\n",
      "  File \"/opt/anaconda3/lib/python3.12/concurrent/futures/_base.py\", line 401, in __get_result\n",
      "    raise self._exception\n",
      "  File \"/opt/anaconda3/lib/python3.12/site-packages/tenacity/__init__.py\", line 478, in __call__\n",
      "    result = fn(*args, **kwargs)\n",
      "             ^^^^^^^^^^^^^^^^^^^\n",
      "  File \"/opt/anaconda3/lib/python3.12/site-packages/google/genai/_api_client.py\", line 948, in _request_once\n",
      "    errors.APIError.raise_for_response(response)\n",
      "  File \"/opt/anaconda3/lib/python3.12/site-packages/google/genai/errors.py\", line 104, in raise_for_response\n",
      "    raise ClientError(status_code, response_json, response)\n",
      "google.genai.errors.ClientError: 429 RESOURCE_EXHAUSTED. {'error': {'code': 429, 'message': 'Resource exhausted. Please try again later. Please refer to https://cloud.google.com/vertex-ai/generative-ai/docs/error-code-429 for more details.', 'status': 'RESOURCE_EXHAUSTED'}}\n",
      "17:51:20 [WARNING] Error on try 1: 429 RESOURCE_EXHAUSTED. {'error': {'code': 429, 'message': 'Resource exhausted. Please try again later. Please refer to https://cloud.google.com/vertex-ai/generative-ai/docs/error-code-429 for more details.', 'status': 'RESOURCE_EXHAUSTED'}}\n",
      "Traceback (most recent call last):\n",
      "  File \"/var/folders/_k/84ry5gsj3bnd86w91nlcyck00000gr/T/ipykernel_88795/3697096895.py\", line 13, in call_vertex_for_image\n",
      "    resp = client.models.generate_content(\n",
      "           ^^^^^^^^^^^^^^^^^^^^^^^^^^^^^^^\n",
      "  File \"/opt/anaconda3/lib/python3.12/site-packages/google/genai/models.py\", line 5898, in generate_content\n",
      "    response = self._generate_content(\n",
      "               ^^^^^^^^^^^^^^^^^^^^^^^\n",
      "  File \"/opt/anaconda3/lib/python3.12/site-packages/google/genai/models.py\", line 4838, in _generate_content\n",
      "    response = self._api_client.request(\n",
      "               ^^^^^^^^^^^^^^^^^^^^^^^^^\n",
      "  File \"/opt/anaconda3/lib/python3.12/site-packages/google/genai/_api_client.py\", line 1067, in request\n",
      "    response = self._request(http_request, stream=False)\n",
      "               ^^^^^^^^^^^^^^^^^^^^^^^^^^^^^^^^^^^^^^^^^\n",
      "  File \"/opt/anaconda3/lib/python3.12/site-packages/google/genai/_api_client.py\", line 958, in _request\n",
      "    return self._retry(self._request_once, http_request, stream)  # type: ignore[no-any-return]\n",
      "           ^^^^^^^^^^^^^^^^^^^^^^^^^^^^^^^^^^^^^^^^^^^^^^^^^^^^^\n",
      "  File \"/opt/anaconda3/lib/python3.12/site-packages/tenacity/__init__.py\", line 475, in __call__\n",
      "    do = self.iter(retry_state=retry_state)\n",
      "         ^^^^^^^^^^^^^^^^^^^^^^^^^^^^^^^^^^\n",
      "  File \"/opt/anaconda3/lib/python3.12/site-packages/tenacity/__init__.py\", line 376, in iter\n",
      "    result = action(retry_state)\n",
      "             ^^^^^^^^^^^^^^^^^^^\n",
      "  File \"/opt/anaconda3/lib/python3.12/site-packages/tenacity/__init__.py\", line 418, in exc_check\n",
      "    raise retry_exc.reraise()\n",
      "          ^^^^^^^^^^^^^^^^^^^\n",
      "  File \"/opt/anaconda3/lib/python3.12/site-packages/tenacity/__init__.py\", line 185, in reraise\n",
      "    raise self.last_attempt.result()\n",
      "          ^^^^^^^^^^^^^^^^^^^^^^^^^^\n",
      "  File \"/opt/anaconda3/lib/python3.12/concurrent/futures/_base.py\", line 449, in result\n",
      "    return self.__get_result()\n",
      "           ^^^^^^^^^^^^^^^^^^^\n",
      "  File \"/opt/anaconda3/lib/python3.12/concurrent/futures/_base.py\", line 401, in __get_result\n",
      "    raise self._exception\n",
      "  File \"/opt/anaconda3/lib/python3.12/site-packages/tenacity/__init__.py\", line 478, in __call__\n",
      "    result = fn(*args, **kwargs)\n",
      "             ^^^^^^^^^^^^^^^^^^^\n",
      "  File \"/opt/anaconda3/lib/python3.12/site-packages/google/genai/_api_client.py\", line 948, in _request_once\n",
      "    errors.APIError.raise_for_response(response)\n",
      "  File \"/opt/anaconda3/lib/python3.12/site-packages/google/genai/errors.py\", line 104, in raise_for_response\n",
      "    raise ClientError(status_code, response_json, response)\n",
      "google.genai.errors.ClientError: 429 RESOURCE_EXHAUSTED. {'error': {'code': 429, 'message': 'Resource exhausted. Please try again later. Please refer to https://cloud.google.com/vertex-ai/generative-ai/docs/error-code-429 for more details.', 'status': 'RESOURCE_EXHAUSTED'}}\n",
      "17:51:41 [WARNING] Error on try 1: 429 RESOURCE_EXHAUSTED. {'error': {'code': 429, 'message': 'Resource exhausted. Please try again later. Please refer to https://cloud.google.com/vertex-ai/generative-ai/docs/error-code-429 for more details.', 'status': 'RESOURCE_EXHAUSTED'}}\n",
      "Traceback (most recent call last):\n",
      "  File \"/var/folders/_k/84ry5gsj3bnd86w91nlcyck00000gr/T/ipykernel_88795/3697096895.py\", line 13, in call_vertex_for_image\n",
      "    resp = client.models.generate_content(\n",
      "           ^^^^^^^^^^^^^^^^^^^^^^^^^^^^^^^\n",
      "  File \"/opt/anaconda3/lib/python3.12/site-packages/google/genai/models.py\", line 5898, in generate_content\n",
      "    response = self._generate_content(\n",
      "               ^^^^^^^^^^^^^^^^^^^^^^^\n",
      "  File \"/opt/anaconda3/lib/python3.12/site-packages/google/genai/models.py\", line 4838, in _generate_content\n",
      "    response = self._api_client.request(\n",
      "               ^^^^^^^^^^^^^^^^^^^^^^^^^\n",
      "  File \"/opt/anaconda3/lib/python3.12/site-packages/google/genai/_api_client.py\", line 1067, in request\n",
      "    response = self._request(http_request, stream=False)\n",
      "               ^^^^^^^^^^^^^^^^^^^^^^^^^^^^^^^^^^^^^^^^^\n",
      "  File \"/opt/anaconda3/lib/python3.12/site-packages/google/genai/_api_client.py\", line 958, in _request\n",
      "    return self._retry(self._request_once, http_request, stream)  # type: ignore[no-any-return]\n",
      "           ^^^^^^^^^^^^^^^^^^^^^^^^^^^^^^^^^^^^^^^^^^^^^^^^^^^^^\n",
      "  File \"/opt/anaconda3/lib/python3.12/site-packages/tenacity/__init__.py\", line 475, in __call__\n",
      "    do = self.iter(retry_state=retry_state)\n",
      "         ^^^^^^^^^^^^^^^^^^^^^^^^^^^^^^^^^^\n",
      "  File \"/opt/anaconda3/lib/python3.12/site-packages/tenacity/__init__.py\", line 376, in iter\n",
      "    result = action(retry_state)\n",
      "             ^^^^^^^^^^^^^^^^^^^\n",
      "  File \"/opt/anaconda3/lib/python3.12/site-packages/tenacity/__init__.py\", line 418, in exc_check\n",
      "    raise retry_exc.reraise()\n",
      "          ^^^^^^^^^^^^^^^^^^^\n",
      "  File \"/opt/anaconda3/lib/python3.12/site-packages/tenacity/__init__.py\", line 185, in reraise\n",
      "    raise self.last_attempt.result()\n",
      "          ^^^^^^^^^^^^^^^^^^^^^^^^^^\n",
      "  File \"/opt/anaconda3/lib/python3.12/concurrent/futures/_base.py\", line 449, in result\n",
      "    return self.__get_result()\n",
      "           ^^^^^^^^^^^^^^^^^^^\n",
      "  File \"/opt/anaconda3/lib/python3.12/concurrent/futures/_base.py\", line 401, in __get_result\n",
      "    raise self._exception\n",
      "  File \"/opt/anaconda3/lib/python3.12/site-packages/tenacity/__init__.py\", line 478, in __call__\n",
      "    result = fn(*args, **kwargs)\n",
      "             ^^^^^^^^^^^^^^^^^^^\n",
      "  File \"/opt/anaconda3/lib/python3.12/site-packages/google/genai/_api_client.py\", line 948, in _request_once\n",
      "    errors.APIError.raise_for_response(response)\n",
      "  File \"/opt/anaconda3/lib/python3.12/site-packages/google/genai/errors.py\", line 104, in raise_for_response\n",
      "    raise ClientError(status_code, response_json, response)\n",
      "google.genai.errors.ClientError: 429 RESOURCE_EXHAUSTED. {'error': {'code': 429, 'message': 'Resource exhausted. Please try again later. Please refer to https://cloud.google.com/vertex-ai/generative-ai/docs/error-code-429 for more details.', 'status': 'RESOURCE_EXHAUSTED'}}\n",
      "17:51:57 [WARNING] Error on try 1: 429 RESOURCE_EXHAUSTED. {'error': {'code': 429, 'message': 'Resource exhausted. Please try again later. Please refer to https://cloud.google.com/vertex-ai/generative-ai/docs/error-code-429 for more details.', 'status': 'RESOURCE_EXHAUSTED'}}\n",
      "Traceback (most recent call last):\n",
      "  File \"/var/folders/_k/84ry5gsj3bnd86w91nlcyck00000gr/T/ipykernel_88795/3697096895.py\", line 13, in call_vertex_for_image\n",
      "    resp = client.models.generate_content(\n",
      "           ^^^^^^^^^^^^^^^^^^^^^^^^^^^^^^^\n",
      "  File \"/opt/anaconda3/lib/python3.12/site-packages/google/genai/models.py\", line 5898, in generate_content\n",
      "    response = self._generate_content(\n",
      "               ^^^^^^^^^^^^^^^^^^^^^^^\n",
      "  File \"/opt/anaconda3/lib/python3.12/site-packages/google/genai/models.py\", line 4838, in _generate_content\n",
      "    response = self._api_client.request(\n",
      "               ^^^^^^^^^^^^^^^^^^^^^^^^^\n",
      "  File \"/opt/anaconda3/lib/python3.12/site-packages/google/genai/_api_client.py\", line 1067, in request\n",
      "    response = self._request(http_request, stream=False)\n",
      "               ^^^^^^^^^^^^^^^^^^^^^^^^^^^^^^^^^^^^^^^^^\n",
      "  File \"/opt/anaconda3/lib/python3.12/site-packages/google/genai/_api_client.py\", line 958, in _request\n",
      "    return self._retry(self._request_once, http_request, stream)  # type: ignore[no-any-return]\n",
      "           ^^^^^^^^^^^^^^^^^^^^^^^^^^^^^^^^^^^^^^^^^^^^^^^^^^^^^\n",
      "  File \"/opt/anaconda3/lib/python3.12/site-packages/tenacity/__init__.py\", line 475, in __call__\n",
      "    do = self.iter(retry_state=retry_state)\n",
      "         ^^^^^^^^^^^^^^^^^^^^^^^^^^^^^^^^^^\n",
      "  File \"/opt/anaconda3/lib/python3.12/site-packages/tenacity/__init__.py\", line 376, in iter\n",
      "    result = action(retry_state)\n",
      "             ^^^^^^^^^^^^^^^^^^^\n",
      "  File \"/opt/anaconda3/lib/python3.12/site-packages/tenacity/__init__.py\", line 418, in exc_check\n",
      "    raise retry_exc.reraise()\n",
      "          ^^^^^^^^^^^^^^^^^^^\n",
      "  File \"/opt/anaconda3/lib/python3.12/site-packages/tenacity/__init__.py\", line 185, in reraise\n",
      "    raise self.last_attempt.result()\n",
      "          ^^^^^^^^^^^^^^^^^^^^^^^^^^\n",
      "  File \"/opt/anaconda3/lib/python3.12/concurrent/futures/_base.py\", line 449, in result\n",
      "    return self.__get_result()\n",
      "           ^^^^^^^^^^^^^^^^^^^\n",
      "  File \"/opt/anaconda3/lib/python3.12/concurrent/futures/_base.py\", line 401, in __get_result\n",
      "    raise self._exception\n",
      "  File \"/opt/anaconda3/lib/python3.12/site-packages/tenacity/__init__.py\", line 478, in __call__\n",
      "    result = fn(*args, **kwargs)\n",
      "             ^^^^^^^^^^^^^^^^^^^\n",
      "  File \"/opt/anaconda3/lib/python3.12/site-packages/google/genai/_api_client.py\", line 948, in _request_once\n",
      "    errors.APIError.raise_for_response(response)\n",
      "  File \"/opt/anaconda3/lib/python3.12/site-packages/google/genai/errors.py\", line 104, in raise_for_response\n",
      "    raise ClientError(status_code, response_json, response)\n",
      "google.genai.errors.ClientError: 429 RESOURCE_EXHAUSTED. {'error': {'code': 429, 'message': 'Resource exhausted. Please try again later. Please refer to https://cloud.google.com/vertex-ai/generative-ai/docs/error-code-429 for more details.', 'status': 'RESOURCE_EXHAUSTED'}}\n",
      "17:52:19 [WARNING] Error on try 1: 429 RESOURCE_EXHAUSTED. {'error': {'code': 429, 'message': 'Resource exhausted. Please try again later. Please refer to https://cloud.google.com/vertex-ai/generative-ai/docs/error-code-429 for more details.', 'status': 'RESOURCE_EXHAUSTED'}}\n",
      "Traceback (most recent call last):\n",
      "  File \"/var/folders/_k/84ry5gsj3bnd86w91nlcyck00000gr/T/ipykernel_88795/3697096895.py\", line 13, in call_vertex_for_image\n",
      "    resp = client.models.generate_content(\n",
      "           ^^^^^^^^^^^^^^^^^^^^^^^^^^^^^^^\n",
      "  File \"/opt/anaconda3/lib/python3.12/site-packages/google/genai/models.py\", line 5898, in generate_content\n",
      "    response = self._generate_content(\n",
      "               ^^^^^^^^^^^^^^^^^^^^^^^\n",
      "  File \"/opt/anaconda3/lib/python3.12/site-packages/google/genai/models.py\", line 4838, in _generate_content\n",
      "    response = self._api_client.request(\n",
      "               ^^^^^^^^^^^^^^^^^^^^^^^^^\n",
      "  File \"/opt/anaconda3/lib/python3.12/site-packages/google/genai/_api_client.py\", line 1067, in request\n",
      "    response = self._request(http_request, stream=False)\n",
      "               ^^^^^^^^^^^^^^^^^^^^^^^^^^^^^^^^^^^^^^^^^\n",
      "  File \"/opt/anaconda3/lib/python3.12/site-packages/google/genai/_api_client.py\", line 958, in _request\n",
      "    return self._retry(self._request_once, http_request, stream)  # type: ignore[no-any-return]\n",
      "           ^^^^^^^^^^^^^^^^^^^^^^^^^^^^^^^^^^^^^^^^^^^^^^^^^^^^^\n",
      "  File \"/opt/anaconda3/lib/python3.12/site-packages/tenacity/__init__.py\", line 475, in __call__\n",
      "    do = self.iter(retry_state=retry_state)\n",
      "         ^^^^^^^^^^^^^^^^^^^^^^^^^^^^^^^^^^\n",
      "  File \"/opt/anaconda3/lib/python3.12/site-packages/tenacity/__init__.py\", line 376, in iter\n",
      "    result = action(retry_state)\n",
      "             ^^^^^^^^^^^^^^^^^^^\n",
      "  File \"/opt/anaconda3/lib/python3.12/site-packages/tenacity/__init__.py\", line 418, in exc_check\n",
      "    raise retry_exc.reraise()\n",
      "          ^^^^^^^^^^^^^^^^^^^\n",
      "  File \"/opt/anaconda3/lib/python3.12/site-packages/tenacity/__init__.py\", line 185, in reraise\n",
      "    raise self.last_attempt.result()\n",
      "          ^^^^^^^^^^^^^^^^^^^^^^^^^^\n",
      "  File \"/opt/anaconda3/lib/python3.12/concurrent/futures/_base.py\", line 449, in result\n",
      "    return self.__get_result()\n",
      "           ^^^^^^^^^^^^^^^^^^^\n",
      "  File \"/opt/anaconda3/lib/python3.12/concurrent/futures/_base.py\", line 401, in __get_result\n",
      "    raise self._exception\n",
      "  File \"/opt/anaconda3/lib/python3.12/site-packages/tenacity/__init__.py\", line 478, in __call__\n",
      "    result = fn(*args, **kwargs)\n",
      "             ^^^^^^^^^^^^^^^^^^^\n",
      "  File \"/opt/anaconda3/lib/python3.12/site-packages/google/genai/_api_client.py\", line 948, in _request_once\n",
      "    errors.APIError.raise_for_response(response)\n",
      "  File \"/opt/anaconda3/lib/python3.12/site-packages/google/genai/errors.py\", line 104, in raise_for_response\n",
      "    raise ClientError(status_code, response_json, response)\n",
      "google.genai.errors.ClientError: 429 RESOURCE_EXHAUSTED. {'error': {'code': 429, 'message': 'Resource exhausted. Please try again later. Please refer to https://cloud.google.com/vertex-ai/generative-ai/docs/error-code-429 for more details.', 'status': 'RESOURCE_EXHAUSTED'}}\n",
      "17:52:38 [WARNING] Error on try 1: 429 RESOURCE_EXHAUSTED. {'error': {'code': 429, 'message': 'Resource exhausted. Please try again later. Please refer to https://cloud.google.com/vertex-ai/generative-ai/docs/error-code-429 for more details.', 'status': 'RESOURCE_EXHAUSTED'}}\n",
      "Traceback (most recent call last):\n",
      "  File \"/var/folders/_k/84ry5gsj3bnd86w91nlcyck00000gr/T/ipykernel_88795/3697096895.py\", line 13, in call_vertex_for_image\n",
      "    resp = client.models.generate_content(\n",
      "           ^^^^^^^^^^^^^^^^^^^^^^^^^^^^^^^\n",
      "  File \"/opt/anaconda3/lib/python3.12/site-packages/google/genai/models.py\", line 5898, in generate_content\n",
      "    response = self._generate_content(\n",
      "               ^^^^^^^^^^^^^^^^^^^^^^^\n",
      "  File \"/opt/anaconda3/lib/python3.12/site-packages/google/genai/models.py\", line 4838, in _generate_content\n",
      "    response = self._api_client.request(\n",
      "               ^^^^^^^^^^^^^^^^^^^^^^^^^\n",
      "  File \"/opt/anaconda3/lib/python3.12/site-packages/google/genai/_api_client.py\", line 1067, in request\n",
      "    response = self._request(http_request, stream=False)\n",
      "               ^^^^^^^^^^^^^^^^^^^^^^^^^^^^^^^^^^^^^^^^^\n",
      "  File \"/opt/anaconda3/lib/python3.12/site-packages/google/genai/_api_client.py\", line 958, in _request\n",
      "    return self._retry(self._request_once, http_request, stream)  # type: ignore[no-any-return]\n",
      "           ^^^^^^^^^^^^^^^^^^^^^^^^^^^^^^^^^^^^^^^^^^^^^^^^^^^^^\n",
      "  File \"/opt/anaconda3/lib/python3.12/site-packages/tenacity/__init__.py\", line 475, in __call__\n",
      "    do = self.iter(retry_state=retry_state)\n",
      "         ^^^^^^^^^^^^^^^^^^^^^^^^^^^^^^^^^^\n",
      "  File \"/opt/anaconda3/lib/python3.12/site-packages/tenacity/__init__.py\", line 376, in iter\n",
      "    result = action(retry_state)\n",
      "             ^^^^^^^^^^^^^^^^^^^\n",
      "  File \"/opt/anaconda3/lib/python3.12/site-packages/tenacity/__init__.py\", line 418, in exc_check\n",
      "    raise retry_exc.reraise()\n",
      "          ^^^^^^^^^^^^^^^^^^^\n",
      "  File \"/opt/anaconda3/lib/python3.12/site-packages/tenacity/__init__.py\", line 185, in reraise\n",
      "    raise self.last_attempt.result()\n",
      "          ^^^^^^^^^^^^^^^^^^^^^^^^^^\n",
      "  File \"/opt/anaconda3/lib/python3.12/concurrent/futures/_base.py\", line 449, in result\n",
      "    return self.__get_result()\n",
      "           ^^^^^^^^^^^^^^^^^^^\n",
      "  File \"/opt/anaconda3/lib/python3.12/concurrent/futures/_base.py\", line 401, in __get_result\n",
      "    raise self._exception\n",
      "  File \"/opt/anaconda3/lib/python3.12/site-packages/tenacity/__init__.py\", line 478, in __call__\n",
      "    result = fn(*args, **kwargs)\n",
      "             ^^^^^^^^^^^^^^^^^^^\n",
      "  File \"/opt/anaconda3/lib/python3.12/site-packages/google/genai/_api_client.py\", line 948, in _request_once\n",
      "    errors.APIError.raise_for_response(response)\n",
      "  File \"/opt/anaconda3/lib/python3.12/site-packages/google/genai/errors.py\", line 104, in raise_for_response\n",
      "    raise ClientError(status_code, response_json, response)\n",
      "google.genai.errors.ClientError: 429 RESOURCE_EXHAUSTED. {'error': {'code': 429, 'message': 'Resource exhausted. Please try again later. Please refer to https://cloud.google.com/vertex-ai/generative-ai/docs/error-code-429 for more details.', 'status': 'RESOURCE_EXHAUSTED'}}\n",
      "17:52:38 [WARNING] Error on try 1: 429 RESOURCE_EXHAUSTED. {'error': {'code': 429, 'message': 'Resource exhausted. Please try again later. Please refer to https://cloud.google.com/vertex-ai/generative-ai/docs/error-code-429 for more details.', 'status': 'RESOURCE_EXHAUSTED'}}\n",
      "Traceback (most recent call last):\n",
      "  File \"/var/folders/_k/84ry5gsj3bnd86w91nlcyck00000gr/T/ipykernel_88795/3697096895.py\", line 13, in call_vertex_for_image\n",
      "    resp = client.models.generate_content(\n",
      "           ^^^^^^^^^^^^^^^^^^^^^^^^^^^^^^^\n",
      "  File \"/opt/anaconda3/lib/python3.12/site-packages/google/genai/models.py\", line 5898, in generate_content\n",
      "    response = self._generate_content(\n",
      "               ^^^^^^^^^^^^^^^^^^^^^^^\n",
      "  File \"/opt/anaconda3/lib/python3.12/site-packages/google/genai/models.py\", line 4838, in _generate_content\n",
      "    response = self._api_client.request(\n",
      "               ^^^^^^^^^^^^^^^^^^^^^^^^^\n",
      "  File \"/opt/anaconda3/lib/python3.12/site-packages/google/genai/_api_client.py\", line 1067, in request\n",
      "    response = self._request(http_request, stream=False)\n",
      "               ^^^^^^^^^^^^^^^^^^^^^^^^^^^^^^^^^^^^^^^^^\n",
      "  File \"/opt/anaconda3/lib/python3.12/site-packages/google/genai/_api_client.py\", line 958, in _request\n",
      "    return self._retry(self._request_once, http_request, stream)  # type: ignore[no-any-return]\n",
      "           ^^^^^^^^^^^^^^^^^^^^^^^^^^^^^^^^^^^^^^^^^^^^^^^^^^^^^\n",
      "  File \"/opt/anaconda3/lib/python3.12/site-packages/tenacity/__init__.py\", line 475, in __call__\n",
      "    do = self.iter(retry_state=retry_state)\n",
      "         ^^^^^^^^^^^^^^^^^^^^^^^^^^^^^^^^^^\n",
      "  File \"/opt/anaconda3/lib/python3.12/site-packages/tenacity/__init__.py\", line 376, in iter\n",
      "    result = action(retry_state)\n",
      "             ^^^^^^^^^^^^^^^^^^^\n",
      "  File \"/opt/anaconda3/lib/python3.12/site-packages/tenacity/__init__.py\", line 418, in exc_check\n",
      "    raise retry_exc.reraise()\n",
      "          ^^^^^^^^^^^^^^^^^^^\n",
      "  File \"/opt/anaconda3/lib/python3.12/site-packages/tenacity/__init__.py\", line 185, in reraise\n",
      "    raise self.last_attempt.result()\n",
      "          ^^^^^^^^^^^^^^^^^^^^^^^^^^\n",
      "  File \"/opt/anaconda3/lib/python3.12/concurrent/futures/_base.py\", line 449, in result\n",
      "    return self.__get_result()\n",
      "           ^^^^^^^^^^^^^^^^^^^\n",
      "  File \"/opt/anaconda3/lib/python3.12/concurrent/futures/_base.py\", line 401, in __get_result\n",
      "    raise self._exception\n",
      "  File \"/opt/anaconda3/lib/python3.12/site-packages/tenacity/__init__.py\", line 478, in __call__\n",
      "    result = fn(*args, **kwargs)\n",
      "             ^^^^^^^^^^^^^^^^^^^\n",
      "  File \"/opt/anaconda3/lib/python3.12/site-packages/google/genai/_api_client.py\", line 948, in _request_once\n",
      "    errors.APIError.raise_for_response(response)\n",
      "  File \"/opt/anaconda3/lib/python3.12/site-packages/google/genai/errors.py\", line 104, in raise_for_response\n",
      "    raise ClientError(status_code, response_json, response)\n",
      "google.genai.errors.ClientError: 429 RESOURCE_EXHAUSTED. {'error': {'code': 429, 'message': 'Resource exhausted. Please try again later. Please refer to https://cloud.google.com/vertex-ai/generative-ai/docs/error-code-429 for more details.', 'status': 'RESOURCE_EXHAUSTED'}}\n",
      "17:53:39 [WARNING] Error on try 1: 429 RESOURCE_EXHAUSTED. {'error': {'code': 429, 'message': 'Resource exhausted. Please try again later. Please refer to https://cloud.google.com/vertex-ai/generative-ai/docs/error-code-429 for more details.', 'status': 'RESOURCE_EXHAUSTED'}}\n",
      "Traceback (most recent call last):\n",
      "  File \"/var/folders/_k/84ry5gsj3bnd86w91nlcyck00000gr/T/ipykernel_88795/3697096895.py\", line 13, in call_vertex_for_image\n",
      "    resp = client.models.generate_content(\n",
      "           ^^^^^^^^^^^^^^^^^^^^^^^^^^^^^^^\n",
      "  File \"/opt/anaconda3/lib/python3.12/site-packages/google/genai/models.py\", line 5898, in generate_content\n",
      "    response = self._generate_content(\n",
      "               ^^^^^^^^^^^^^^^^^^^^^^^\n",
      "  File \"/opt/anaconda3/lib/python3.12/site-packages/google/genai/models.py\", line 4838, in _generate_content\n",
      "    response = self._api_client.request(\n",
      "               ^^^^^^^^^^^^^^^^^^^^^^^^^\n",
      "  File \"/opt/anaconda3/lib/python3.12/site-packages/google/genai/_api_client.py\", line 1067, in request\n",
      "    response = self._request(http_request, stream=False)\n",
      "               ^^^^^^^^^^^^^^^^^^^^^^^^^^^^^^^^^^^^^^^^^\n",
      "  File \"/opt/anaconda3/lib/python3.12/site-packages/google/genai/_api_client.py\", line 958, in _request\n",
      "    return self._retry(self._request_once, http_request, stream)  # type: ignore[no-any-return]\n",
      "           ^^^^^^^^^^^^^^^^^^^^^^^^^^^^^^^^^^^^^^^^^^^^^^^^^^^^^\n",
      "  File \"/opt/anaconda3/lib/python3.12/site-packages/tenacity/__init__.py\", line 475, in __call__\n",
      "    do = self.iter(retry_state=retry_state)\n",
      "         ^^^^^^^^^^^^^^^^^^^^^^^^^^^^^^^^^^\n",
      "  File \"/opt/anaconda3/lib/python3.12/site-packages/tenacity/__init__.py\", line 376, in iter\n",
      "    result = action(retry_state)\n",
      "             ^^^^^^^^^^^^^^^^^^^\n",
      "  File \"/opt/anaconda3/lib/python3.12/site-packages/tenacity/__init__.py\", line 418, in exc_check\n",
      "    raise retry_exc.reraise()\n",
      "          ^^^^^^^^^^^^^^^^^^^\n",
      "  File \"/opt/anaconda3/lib/python3.12/site-packages/tenacity/__init__.py\", line 185, in reraise\n",
      "    raise self.last_attempt.result()\n",
      "          ^^^^^^^^^^^^^^^^^^^^^^^^^^\n",
      "  File \"/opt/anaconda3/lib/python3.12/concurrent/futures/_base.py\", line 449, in result\n",
      "    return self.__get_result()\n",
      "           ^^^^^^^^^^^^^^^^^^^\n",
      "  File \"/opt/anaconda3/lib/python3.12/concurrent/futures/_base.py\", line 401, in __get_result\n",
      "    raise self._exception\n",
      "  File \"/opt/anaconda3/lib/python3.12/site-packages/tenacity/__init__.py\", line 478, in __call__\n",
      "    result = fn(*args, **kwargs)\n",
      "             ^^^^^^^^^^^^^^^^^^^\n",
      "  File \"/opt/anaconda3/lib/python3.12/site-packages/google/genai/_api_client.py\", line 948, in _request_once\n",
      "    errors.APIError.raise_for_response(response)\n",
      "  File \"/opt/anaconda3/lib/python3.12/site-packages/google/genai/errors.py\", line 104, in raise_for_response\n",
      "    raise ClientError(status_code, response_json, response)\n",
      "google.genai.errors.ClientError: 429 RESOURCE_EXHAUSTED. {'error': {'code': 429, 'message': 'Resource exhausted. Please try again later. Please refer to https://cloud.google.com/vertex-ai/generative-ai/docs/error-code-429 for more details.', 'status': 'RESOURCE_EXHAUSTED'}}\n",
      "17:55:42 [WARNING] Error on try 1: 429 RESOURCE_EXHAUSTED. {'error': {'code': 429, 'message': 'Resource exhausted. Please try again later. Please refer to https://cloud.google.com/vertex-ai/generative-ai/docs/error-code-429 for more details.', 'status': 'RESOURCE_EXHAUSTED'}}\n",
      "Traceback (most recent call last):\n",
      "  File \"/var/folders/_k/84ry5gsj3bnd86w91nlcyck00000gr/T/ipykernel_88795/3697096895.py\", line 13, in call_vertex_for_image\n",
      "    resp = client.models.generate_content(\n",
      "           ^^^^^^^^^^^^^^^^^^^^^^^^^^^^^^^\n",
      "  File \"/opt/anaconda3/lib/python3.12/site-packages/google/genai/models.py\", line 5898, in generate_content\n",
      "    response = self._generate_content(\n",
      "               ^^^^^^^^^^^^^^^^^^^^^^^\n",
      "  File \"/opt/anaconda3/lib/python3.12/site-packages/google/genai/models.py\", line 4838, in _generate_content\n",
      "    response = self._api_client.request(\n",
      "               ^^^^^^^^^^^^^^^^^^^^^^^^^\n",
      "  File \"/opt/anaconda3/lib/python3.12/site-packages/google/genai/_api_client.py\", line 1067, in request\n",
      "    response = self._request(http_request, stream=False)\n",
      "               ^^^^^^^^^^^^^^^^^^^^^^^^^^^^^^^^^^^^^^^^^\n",
      "  File \"/opt/anaconda3/lib/python3.12/site-packages/google/genai/_api_client.py\", line 958, in _request\n",
      "    return self._retry(self._request_once, http_request, stream)  # type: ignore[no-any-return]\n",
      "           ^^^^^^^^^^^^^^^^^^^^^^^^^^^^^^^^^^^^^^^^^^^^^^^^^^^^^\n",
      "  File \"/opt/anaconda3/lib/python3.12/site-packages/tenacity/__init__.py\", line 475, in __call__\n",
      "    do = self.iter(retry_state=retry_state)\n",
      "         ^^^^^^^^^^^^^^^^^^^^^^^^^^^^^^^^^^\n",
      "  File \"/opt/anaconda3/lib/python3.12/site-packages/tenacity/__init__.py\", line 376, in iter\n",
      "    result = action(retry_state)\n",
      "             ^^^^^^^^^^^^^^^^^^^\n",
      "  File \"/opt/anaconda3/lib/python3.12/site-packages/tenacity/__init__.py\", line 418, in exc_check\n",
      "    raise retry_exc.reraise()\n",
      "          ^^^^^^^^^^^^^^^^^^^\n",
      "  File \"/opt/anaconda3/lib/python3.12/site-packages/tenacity/__init__.py\", line 185, in reraise\n",
      "    raise self.last_attempt.result()\n",
      "          ^^^^^^^^^^^^^^^^^^^^^^^^^^\n",
      "  File \"/opt/anaconda3/lib/python3.12/concurrent/futures/_base.py\", line 449, in result\n",
      "    return self.__get_result()\n",
      "           ^^^^^^^^^^^^^^^^^^^\n",
      "  File \"/opt/anaconda3/lib/python3.12/concurrent/futures/_base.py\", line 401, in __get_result\n",
      "    raise self._exception\n",
      "  File \"/opt/anaconda3/lib/python3.12/site-packages/tenacity/__init__.py\", line 478, in __call__\n",
      "    result = fn(*args, **kwargs)\n",
      "             ^^^^^^^^^^^^^^^^^^^\n",
      "  File \"/opt/anaconda3/lib/python3.12/site-packages/google/genai/_api_client.py\", line 948, in _request_once\n",
      "    errors.APIError.raise_for_response(response)\n",
      "  File \"/opt/anaconda3/lib/python3.12/site-packages/google/genai/errors.py\", line 104, in raise_for_response\n",
      "    raise ClientError(status_code, response_json, response)\n",
      "google.genai.errors.ClientError: 429 RESOURCE_EXHAUSTED. {'error': {'code': 429, 'message': 'Resource exhausted. Please try again later. Please refer to https://cloud.google.com/vertex-ai/generative-ai/docs/error-code-429 for more details.', 'status': 'RESOURCE_EXHAUSTED'}}\n",
      "✅ All done: (10, 3)\n"
     ]
    }
   ],
   "source": [
    "ouput_df = process_all_images_in_batches(all_images)\n",
    "print(\"✅ All done:\", ouput_df.shape)"
   ]
  },
  {
   "cell_type": "code",
   "execution_count": 75,
   "metadata": {},
   "outputs": [],
   "source": [
    "ouput_df.to_csv('../output/free_emo_abstract.csv', index=False)"
   ]
  },
  {
   "cell_type": "markdown",
   "metadata": {},
   "source": [
    "### Process images & save output"
   ]
  },
  {
   "cell_type": "markdown",
   "metadata": {},
   "source": [
    "------END-------"
   ]
  },
  {
   "cell_type": "markdown",
   "metadata": {},
   "source": [
    "### 882 images in total"
   ]
  }
 ],
 "metadata": {
  "kernelspec": {
   "display_name": "base",
   "language": "python",
   "name": "python3"
  },
  "language_info": {
   "codemirror_mode": {
    "name": "ipython",
    "version": 3
   },
   "file_extension": ".py",
   "mimetype": "text/x-python",
   "name": "python",
   "nbconvert_exporter": "python",
   "pygments_lexer": "ipython3",
   "version": "3.12.3"
  }
 },
 "nbformat": 4,
 "nbformat_minor": 2
}
